<?xml version="1.0"?>
<robot name="index">
	
	<material name="red">
		<color rgba="255 0 0 1"/>	
	</material>
	<material name="green">
		<color rgba="0 255 0 1"/>	
	</material>
	<material name="blue">
		<color rgba="192 192 192 1"/>	
	</material>
	<material name="grey">
		<color rgba="255 255 0 1"/>	
	</material>

	<link name="base_link">
		<visual>
			<geometry>
				<box size="0.10 0.04 0.11" />
			</geometry>
			<material name="green"/>
		</visual>
	</link>

	<!-- Index -->
	<link name="index_phalanx_base">
		<visual>
			<geometry>
				<cylinder length="0.04" radius="0.02" />
			</geometry>
			<material name="blue"/>
		</visual>
	</link>	
	<link name="index_phalanx_middle">
		<visual>
			<geometry>
				<cylinder length="0.03" radius="0.009" />
			</geometry>
			<material name="red"/>
		</visual>
	</link>
	<link name="index_phalanx_end">
		<visual>
			<geometry>
				<cylinder length="0.03" radius="0.006" />
			</geometry>
			<material name="grey"/>
		</visual>
	</link>
	
	<joint name="base_link_to_index_base" type="revolute">
		<axis xyz="1 0 0"/>
		<parent link="base_link"/>
		<child link="index_phalanx_base"/>
		<limit effort="1000" upper="1.57" lower="-1.65" velocity="0.5"/>
		<origin xyz="0.03 0.0 0.05"/>
	</joint>
	<joint name="index_base_to_middle" type="revolute">
		<axis xyz="1 0 0"/>
		<parent link="index_phalanx_base"/>
		<child link="index_phalanx_middle"/>
		<limit effort="1000" upper="0" lower="-1.65" velocity="0.5"/>
		<origin xyz="0.0 0.0 0.03"/>
	</joint>
	<joint name="index_middle_to_end" type="revolute">
		<axis xyz="1 0 0"/>
		<parent link="index_phalanx_middle"/>
		<child link="index_phalanx_end"/>
		<limit effort="1000" upper="0" lower="-1.57" velocity="0.5"/>
		<origin xyz="0.0 0.0 0.025"/>
	</joint>

<!-- annulaire -->
<link name="ring_phalange_base">
		<visual>
			<geometry>
				<cylinder length="0.03" radius="0.01"/>
			</geometry>
			<material name="coral"/>
			<origin xyz="0 0 0.015"/>
		</visual>
	</link>

	<link name="ring_phalange_middle">
		<visual>
			<geometry>
				<cylinder length="0.025" radius="0.008"/>
			</geometry>
			<material name="orange"/>
			<origin xyz="0 0 0.0125"/>
		</visual>
	</link>

	<link name="ring_phalange_end">
		<visual>
			<geometry>
				<cylinder length="0.025" radius="0.005"/>
			</geometry>
			<material name="red"/>
			<origin xyz="0 0 0.0125"/>
		</visual>
	</link>
	

	<joint name="base_link_to_ring_base" type="revolute">
		<axis xyz="1 0 0"/>
		<parent link="base_link"/>
		<child link="ring_phalange_base"/>
		<limit effort="1000" upper="1.57" lower="-1.65" velocity="0.5"/>
		<origin xyz="-0.015 0.0 0.05"/>
	</joint>
	<joint name="ring_base_to_middle" type="revolute">
		<axis xyz="1 0 0"/>
		<parent link="ring_phalange_base"/>
		<child link="ring_phalange_middle"/>
		<limit effort="1000" upper="0" lower="-1.65" velocity="0.5"/>
		<origin xyz="0.0 0.0 0.03"/>
	</joint>
	<joint name="ring_middle_to_end" type="revolute">
		<axis xyz="1 0 0"/>
		<parent link="ring_phalange_middle"/>
		<child link="ring_phalange_end"/>
		<limit effort="1000" upper="0" lower="-1.57" velocity="0.5"/>
		<origin xyz="0.0 0.0 0.025"/>
	</joint>


	<!-- majeur -->
	<link name="middle_phalange_base">
		<visual>
			<geometry>
				<cylinder length="0.03" radius="0.01"/>
			</geometry>
			<material name="coral"/>
			<origin xyz="0 0 0.015"/>
		</visual>
	</link>

	<link name="middle_phalange_middle">
		<visual>
			<geometry>
				<cylinder length="0.03" radius="0.008"/>
			</geometry>
			<material name="orange"/>
			<origin xyz="0 0 0.015"/>
		</visual>
	</link>

	<link name="middle_phalange_end">
		<visual>
			<geometry>
				<cylinder length="0.03" radius="0.005"/>
			</geometry>
			<material name="red"/>
			<origin xyz="0 0 0.015"/>
		</visual>
	</link>
	

	<joint name="base_link_to_middle_base" type="revolute">
		<axis xyz="1 0 0"/>
		<parent link="base_link"/>
		<child link="middle_phalange_base"/>
		<limit effort="1000" upper="1.57" lower="-1.65" velocity="0.5"/>
		<origin xyz="0.008 0.0 0.05"/>
	</joint>
	<joint name="middle_base_to_middle" type="revolute">
		<axis xyz="1 0 0"/>
		<parent link="middle_phalange_base"/>
		<child link="middle_phalange_middle"/>
		<limit effort="1000" upper="0" lower="-1.65" velocity="0.5"/>
		<origin xyz="0.0 0.0 0.03"/>
	</joint>
	<joint name="middle_middle_to_end" type="revolute">
		<axis xyz="1 0 0"/>
		<parent link="middle_phalange_middle"/>
		<child link="middle_phalange_end"/>
		<limit effort="1000" upper="0" lower="-1.57" velocity="0.5"/>
		<origin xyz="0.0 0.0 0.03"/>
	</joint>
	<!-- Pinky -->
	<link name="pinky_phalange_base">
		<visual>
			<geometry>
				<cylinder length="0.02" radius="0.005"/>
			</geometry>
			<material name="coral"/>
			<origin xyz="0 0 0.01"/>
		</visual>
	</link>

	<link name="pinky_phalange_middle">
		<visual>
			<geometry>
				<cylinder length="0.02" radius="0.005"/>
			</geometry>
			<material name="orange"/>
			<origin xyz="0 0 0.010"/>
		</visual>
	</link>

	<link name="pinky_phalange_end">
		<visual>
			<geometry>
				<cylinder length="0.02" radius="0.005"/>
			</geometry>
			<material name="red"/>
			<origin xyz="0 0 0.010"/>
		</visual>
	</link>
	

	<joint name="base_link_to_pinky_base" type="revolute">
		<axis xyz="1 0 0"/>
		<parent link="base_link"/>
		<child link="pinky_phalange_base"/>
		<limit effort="1000" upper="1.57" lower="-1.65" velocity="0.5"/>
		<origin xyz="-0.035 0.0 0.05"/>
	</joint>
	<joint name="pinky_base_to_middle" type="revolute">
		<axis xyz="1 0 0"/>
		<parent link="pinky_phalange_base"/>
		<child link="pinky_phalange_middle"/>
		<limit effort="1000" upper="0" lower="-1.65" velocity="0.5"/>
		<origin xyz="0.0 0.0 0.02"/>
	</joint>
	<joint name="pinky_middle_to_end" type="revolute">
		<axis xyz="1 0 0"/>
		<parent link="pinky_phalange_middle"/>
		<child link="pinky_phalange_end"/>
		<limit effort="1000" upper="0" lower="-1.57" velocity="0.5"/>
		<origin xyz="0.0 0.0 0.02"/>
	</joint>

<!--Thumb-->
	<link name="thumb_phalange_base">
			<visual>
				<geometry>
					<cylinder length="0.03" radius="0.01"/>
				</geometry>
				<material name="coral"/>
				<origin xyz="0 0 0.0150"/>
			</visual>
	</link>
	<link name="thumb_phalange_end">
			<visual>
				<geometry>
					<cylinder length="0.02" radius="0.008"/>
				</geometry>
				<material name="red"/>
				<origin xyz="0 0 0.01"/>
			</visual>
	</link>

	<joint name="thumb_base_palm" type="revolute">
		<axis xyz="1 0 0"/>
		<parent link="base_link"/>
		<child link="thumb_phalange_base"/>
		<origin xyz="0.04 0 -0.025" rpy="0 1.57 0"/>
		<limit effort="1000" upper="0" lower="-1.57" velocity="0.5"/>
	</joint>
	<joint name="thumb_end_to_thumb_base" type="revolute">
		<axis xyz="1 0 0"/>
		<parent link="thumb_phalange_base"/>
		<child link="thumb_phalange_end"/>
		<origin xyz="0 0 0.03" rpy="0 0 0"/>
		<limit effort="1000" upper="0" lower="-1.0" velocity="0.5"/>
	</joint>

</robot>
	
